Workbook
Name AgentList: '_Helper'!$A$1:$A$77

Sheet Agent_Definitions
A1: Agent Definitions
A2: Define your custom agents here. These will be available in the Workflow tab dropdown.
A3: Agent_ID | B3: AgentType | C3: Category | D3: Description | E3: Input_Fields | F3: Output_Field | G3: Default_Prompt | H3: Default_Context | I3: Tool_Source | J3: Available_Tools
A4: my_custom_llm | B4: claude | C4: Custom | D4: My custom Claude agent for specific tasks | E4: query|context | F4: answer | G4: You are an expert assistant. Answer the query based on the context provided. | H4: {"provider": "anthropic", "model": "claude-3-5-sonnet-20241022", "temperature": 0.5}

Sheet Prompts
A1: Reusable Prompts
A2: Define reusable prompts here. Reference them in the Workflow tab using @Prompt_ID
A3: Prompt_ID | B3: Prompt_Name | C3: Prompt_Text | D3: Description
A4: system_helpful | B4: Helpful Assistant | C4: You are a helpful, harmless, and honest AI assistant. Provide clear, accurate, and useful information. | D4: General purpose system prompt
A5: system_expert | B5: Domain Expert | C5: You are an expert in {domain}. Provide detailed, accurate, and professional responses based on your expertise. | D5: Expert persona prompt with domain placeholder
A6: summarize_text | B6: Summarize Text | C6: Summarize the following text in a clear and concise manner. Focus on the key points and main ideas: {text} | D6: Text summarization prompt
A7: extract_json | B7: Extract to JSON | C7: Extract the relevant information from the following text and return it as valid JSON: {text} Return only the JSON, no explanation. | D7: Structured data extraction
A8: analyze_sentiment | B8: Sentiment Analysis | C8: Analyze the sentiment of the following text. Classify it as positive, negative, or neutral, and explain why: {text} | D8: Sentiment analysis prompt

Sheet Workflow
A1: Workflow Definition
A2: Define your workflow here. Select agents from dropdown or use builtin_* agents. The CSV_Export sheet will generate the final CSV.
A3: GraphName | B3: Node | C3: Agent_ID | D3: AgentType | E3: Prompt | F3: Description | G3: Context | H3: Input_Fields | I3: Output_Field | J3: Edge | K3: Success_Next | L3: Failure_Next | M3: Notes
A4: ExampleWorkflow | B4: Start | C4: builtin_input | E4: What would you like help with today? | F4: Get initial user input | J4: Process | M4: Entry point
A5: ExampleWorkflow | B5: Process | C5: builtin_claude | E5: @system_helpful | F5: Process user request | K5: Respond | L5: HandleError | M5: Main processing
A6: ExampleWorkflow | B6: Respond | C6: builtin_echo | F6: Return response to user | M6: Output
A7: ExampleWorkflow | B7: HandleError | C7: builtin_default | E7: An error occurred. Please try again. | F7: Handle errors | M7: Error handler

Sheet Builtin_Agents
A1: Builtin Agents Reference
A2: Reference sheet for all builtin agents. These can be selected directly in the Workflow tab.
A3: Agent_ID | B3: AgentType | C3: Category | D3: Description | E3: Input_Fields | F3: Output_Field | G3: Default_Prompt | H3: Default_Context | I3: Tool_Source | J3: Available_Tools
A4: builtin_echo | B4: echo | C4: Core | D4: Pass through and format data between nodes | E4: message | F4: message | H4: {}
A5: builtin_default | B5: default | C5: Core | D5: Default agent that logs and returns message | E5: message | F5: response | H5: {}
A6: builtin_input | B6: input | C6: Core | D6: Prompt user for input | E6: prompt | F6: user_input | G6: Please provide input: | H6: {}
A7: builtin_branching | B7: branching | C7: Core | D7: Route based on field conditions | E7: status | F7: result | H7: {"success_field": "status", "success_values": ["ok", "success", "true"], "failure_values": ["error", "failed", "false"]}
A8: builtin_success | B8: success | C8: Core | D8: Always returns success (for testing) | E8: message | F8: result | H8: {}
A9: builtin_failure | B9: failure | C9: Core | D9: Always returns failure (for testing) | E9: message | F9: result | H9: {}
A10: builtin_suspend | B10: suspend | C10: Core | D10: Pause for external processing | E10: state | F10: resumed_state | H10: {"suspension_reason": "Awaiting external process"}
A11: builtin_human_approval | B11: human | C11: Core | D11: Human approval interaction | E11: request | F11: approval | G11: Please approve the following: | H11: {"interaction_type": "approval", "timeout_seconds": 3600}
A12: builtin_human_choice | B12: human | C12: Core | D12: Human choice from options | E12: options | F12: selection | G12: Please select an option: | H12: {"interaction_type": "choice", "options": ["Option A", "Option B", "Option C"], "timeout_seconds": 3600}
A13: builtin_human_text | B13: human | C13: Core | D13: Human text input | E13: prompt | F13: response | G13: Please provide your input: | H13: {"interaction_type": "text_input", "timeout_seconds": 3600}
A14: builtin_human_edit | B14: human | C14: Core | D14: Human edit existing content | E14: content | F14: edited_content | G14: Please review and edit: | H14: {"interaction_type": "edit", "timeout_seconds": 3600}
A15: builtin_graph | B15: graph | C15: Core | D15: Execute a subgraph | E15: input_data | F15: output_data | H15: {"subgraph_name": "SubWorkflowName"}
A16: builtin_claude | B16: claude | C16: LLM | D16: Anthropic Claude LLM agent | E16: message | F16: response | G16: You are a helpful assistant. | H16: {"provider": "anthropic", "model": "claude-3-5-sonnet-20241022", "temperature": 0.7, "max_tokens": 1000}
A17: builtin_gpt | B17: gpt | C17: LLM | D17: OpenAI GPT LLM agent | E17: message | F17: response | G17: You are a helpful assistant. | H17: {"provider": "openai", "model": "gpt-4", "temperature": 0.7, "max_tokens": 1000}
A18: builtin_gemini | B18: gemini | C18: LLM | D18: Google Gemini LLM agent | E18: message | F18: response | G18: You are a helpful assistant. | H18: {"provider": "google", "model": "gemini-pro", "temperature": 0.7, "max_tokens": 1000}
A19: builtin_llm_structured | B19: llm | C19: LLM | D19: Generic LLM with structured output | E19: message|context | F19: structured_response | G19: Process the input and return structured data. | H19: {"provider": "anthropic", "model": "claude-3-5-sonnet-20241022", "temperature": 0.0, "max_tokens": 2000, "output_format": "json"}
A20: builtin_csv_reader | B20: csv_reader | C20: Storage | D20: Read data from CSV file | E20: file_path | F20: data | H20: {"encoding": "utf-8", "delimiter": ","}
A21: builtin_csv_writer | B21: csv_writer | C21: Storage | D21: Write data to CSV file | E21: data|file_path | F21: status | H21: {"encoding": "utf-8", "delimiter": ",", "mode": "write"}
A22: builtin_json_reader | B22: json_reader | C22: Storage | D22: Read data from JSON file | E22: file_path | F22: data | H22: {"encoding": "utf-8"}
A23: builtin_json_writer | B23: json_writer | C23: Storage | D23: Write data to JSON file | E23: data|file_path | F23: status | H23: {"encoding": "utf-8", "indent": 2}
A24: builtin_file_reader | B24: file_reader | C24: Storage | D24: Read text from file | E24: file_path | F24: content | H24: {"encoding": "utf-8"}
A25: builtin_file_writer | B25: file_writer | C25: Storage | D25: Write text to file | E25: content|file_path | F25: status | H25: {"encoding": "utf-8", "mode": "write"}
A26: builtin_vector_reader | B26: vector_reader | C26: Storage | D26: Query vector database | E26: query|top_k | F26: results | H26: {"collection": "default", "top_k": 5}
A27: builtin_vector_writer | B27: vector_writer | C27: Storage | D27: Write to vector database | E27: documents|embeddings | F27: status | H27: {"collection": "default"}
A28: builtin_summary | B28: summary | C28: Mixed | D28: Summarize execution results | E28: execution_data | F28: summary | G28: Summarize the execution results. | H28: {"format": "markdown", "include_metrics": true}
A29: builtin_orchestrator | B29: orchestrator | C29: Mixed | D29: Route to best node based on input | E29: input|options | F29: selected_node | G29: Select the best option for the given input. | H29: {"selection_strategy": "llm_based"}
A30: builtin_tool_agent | B30: tool_agent | C30: Mixed | D30: Select and execute tools | E30: task | F30: result | G30: Execute the appropriate tool for the task. | H30: {"max_iterations": 5} | I30: agentmap.tools | J30: search|calculate|fetch

Sheet CSV_Export
A1: CSV Export (Copy this sheet to export as CSV)
A2: This sheet shows the final CSV output. Copy all data (Ctrl+C) and paste into a text file, or use File > Save As > CSV.
A3: GraphName | B3: Node | C3: AgentType | D3: Prompt | E3: Description | F3: Context | G3: Input_Fields | H3: Output_Field | I3: Edge | J3: Success_Next | K3: Failure_Next
A4: =IF(Workflow!A4="","",Workflow!A4) | B4: =IF(Workflow!B4="","",Workflow!B4) | C4: =IF(Workflow!B4="","",IF(Workflow!D4<>"",Workflow!D4,IFERROR(VLOOKUP(Workflow!C4,Builtin_Agents!A:B,2,FALSE),IFERROR(VLOOKUP(Workflow!C4,Agent_Definitions!A:B,2,FALSE),"")))) | D4: =IF(Workflow!B4="","",IF(LEFT(Workflow!E4,1)="@",IFERROR(VLOOKUP(MID(Workflow!E4,2,100),Prompts!A:C,3,FALSE),Workflow!E4),Workflow!E4)) | E4: =IF(Workflow!B4="","",Workflow!F4) | F4: =IF(Workflow!B4="","",IF(Workflow!G4<>"",Workflow!G4,IFERROR(VLOOKUP(Workflow!C4,Builtin_Agents!A:H,8,FALSE),IFERROR(VLOOKUP(Workflow!C4,Agent_Definitions!A:H,8,FALSE),"")))) | G4: =IF(Workflow!B4="","",IF(Workflow!H4<>"",Workflow!H4,IFERROR(VLOOKUP(Workflow!C4,Builtin_Agents!A:E,5,FALSE),IFERROR(VLOOKUP(Workflow!C4,Agent_Definitions!A:E,5,FALSE),"")))) | H4: =IF(Workflow!B4="","",IF(Workflow!I4<>"",Workflow!I4,IFERROR(VLOOKUP(Workflow!C4,Builtin_Agents!A:F,6,FALSE),IFERROR(VLOOKUP(Workflow!C4,Agent_Definitions!A:F,6,FALSE),"")))) | I4: =IF(Workflow!B4="","",Workflow!J4) | J4: =IF(Workflow!B4="","",Workflow!K4) | K4: =IF(Workflow!B4="","",Workflow!L4)
A5: =IF(Workflow!A5="","",Workflow!A5) | B5: =IF(Workflow!B5="","",Workflow!B5) | C5: =IF(Workflow!B5="","",IF(Workflow!D5<>"",Workflow!D5,IFERROR(VLOOKUP(Workflow!C5,Builtin_Agents!A:B,2,FALSE),IFERROR(VLOOKUP(Workflow!C5,Agent_Definitions!A:B,2,FALSE),"")))) | D5: =IF(Workflow!B5="","",IF(LEFT(Workflow!E5,1)="@",IFERROR(VLOOKUP(MID(Workflow!E5,2,100),Prompts!A:C,3,FALSE),Workflow!E5),Workflow!E5)) | E5: =IF(Workflow!B5="","",Workflow!F5) | F5: =IF(Workflow!B5="","",IF(Workflow!G5<>"",Workflow!G5,IFERROR(VLOOKUP(Workflow!C5,Builtin_Agents!A:H,8,FALSE),IFERROR(VLOOKUP(Workflow!C5,Agent_Definitions!A:H,8,FALSE),"")))) | G5: =IF(Workflow!B5="","",IF(Workflow!H5<>"",Workflow!H5,IFERROR(VLOOKUP(Workflow!C5,Builtin_Agents!A:E,5,FALSE),IFERROR(VLOOKUP(Workflow!C5,Agent_Definitions!A:E,5,FALSE),"")))) | H5: =IF(Workflow!B5="","",IF(Workflow!I5<>"",Workflow!I5,IFERROR(VLOOKUP(Workflow!C5,Builtin_Agents!A:F,6,FALSE),IFERROR(VLOOKUP(Workflow!C5,Agent_Definitions!A:F,6,FALSE),"")))) | I5: =IF(Workflow!B5="","",Workflow!J5) | J5: =IF(Workflow!B5="","",Workflow!K5) | K5: =IF(Workflow!B5="","",Workflow!L5)
A6: =IF(Workflow!A6="","",Workflow!A6) | B6: =IF(Workflow!B6="","",Workflow!B6) | C6: =IF(Workflow!B6="","",IF(Workflow!D6<>"",Workflow!D6,IFERROR(VLOOKUP(Workflow!C6,Builtin_Agents!A:B,2,FALSE),IFERROR(VLOOKUP(Workflow!C6,Agent_Definitions!A:B,2,FALSE),"")))) | D6: =IF(Workflow!B6="","",IF(LEFT(Workflow!E6,1)="@",IFERROR(VLOOKUP(MID(Workflow!E6,2,100),Prompts!A:C,3,FALSE),Workflow!E6),Workflow!E6)) | E6: =IF(Workflow!B6="","",Workflow!F6) | F6: =IF(Workflow!B6="","",IF(Workflow!G6<>"",Workflow!G6,IFERROR(VLOOKUP(Workflow!C6,Builtin_Agents!A:H,8,FALSE),IFERROR(VLOOKUP(Workflow!C6,Agent_Definitions!A:H,8,FALSE),"")))) | G6: =IF(Workflow!B6="","",IF(Workflow!H6<>"",Workflow!H6,IFERROR(VLOOKUP(Workflow!C6,Builtin_Agents!A:E,5,FALSE),IFERROR(VLOOKUP(Workflow!C6,Agent_Definitions!A:E,5,FALSE),"")))) | H6: =IF(Workflow!B6="","",IF(Workflow!I6<>"",Workflow!I6,IFERROR(VLOOKUP(Workflow!C6,Builtin_Agents!A:F,6,FALSE),IFERROR(VLOOKUP(Workflow!C6,Agent_Definitions!A:F,6,FALSE),"")))) | I6: =IF(Workflow!B6="","",Workflow!J6) | J6: =IF(Workflow!B6="","",Workflow!K6) | K6: =IF(Workflow!B6="","",Workflow!L6)
A7: =IF(Workflow!A7="","",Workflow!A7) | B7: =IF(Workflow!B7="","",Workflow!B7) | C7: =IF(Workflow!B7="","",IF(Workflow!D7<>"",Workflow!D7,IFERROR(VLOOKUP(Workflow!C7,Builtin_Agents!A:B,2,FALSE),IFERROR(VLOOKUP(Workflow!C7,Agent_Definitions!A:B,2,FALSE),"")))) | D7: =IF(Workflow!B7="","",IF(LEFT(Workflow!E7,1)="@",IFERROR(VLOOKUP(MID(Workflow!E7,2,100),Prompts!A:C,3,FALSE),Workflow!E7),Workflow!E7)) | E7: =IF(Workflow!B7="","",Workflow!F7) | F7: =IF(Workflow!B7="","",IF(Workflow!G7<>"",Workflow!G7,IFERROR(VLOOKUP(Workflow!C7,Builtin_Agents!A:H,8,FALSE),IFERROR(VLOOKUP(Workflow!C7,Agent_Definitions!A:H,8,FALSE),"")))) | G7: =IF(Workflow!B7="","",IF(Workflow!H7<>"",Workflow!H7,IFERROR(VLOOKUP(Workflow!C7,Builtin_Agents!A:E,5,FALSE),IFERROR(VLOOKUP(Workflow!C7,Agent_Definitions!A:E,5,FALSE),"")))) | H7: =IF(Workflow!B7="","",IF(Workflow!I7<>"",Workflow!I7,IFERROR(VLOOKUP(Workflow!C7,Builtin_Agents!A:F,6,FALSE),IFERROR(VLOOKUP(Workflow!C7,Agent_Definitions!A:F,6,FALSE),"")))) | I7: =IF(Workflow!B7="","",Workflow!J7) | J7: =IF(Workflow!B7="","",Workflow!K7) | K7: =IF(Workflow!B7="","",Workflow!L7)
A8: =IF(Workflow!A8="","",Workflow!A8) | B8: =IF(Workflow!B8="","",Workflow!B8) | C8: =IF(Workflow!B8="","",IF(Workflow!D8<>"",Workflow!D8,IFERROR(VLOOKUP(Workflow!C8,Builtin_Agents!A:B,2,FALSE),IFERROR(VLOOKUP(Workflow!C8,Agent_Definitions!A:B,2,FALSE),"")))) | D8: =IF(Workflow!B8="","",IF(LEFT(Workflow!E8,1)="@",IFERROR(VLOOKUP(MID(Workflow!E8,2,100),Prompts!A:C,3,FALSE),Workflow!E8),Workflow!E8)) | E8: =IF(Workflow!B8="","",Workflow!F8) | F8: =IF(Workflow!B8="","",IF(Workflow!G8<>"",Workflow!G8,IFERROR(VLOOKUP(Workflow!C8,Builtin_Agents!A:H,8,FALSE),IFERROR(VLOOKUP(Workflow!C8,Agent_Definitions!A:H,8,FALSE),"")))) | G8: =IF(Workflow!B8="","",IF(Workflow!H8<>"",Workflow!H8,IFERROR(VLOOKUP(Workflow!C8,Builtin_Agents!A:E,5,FALSE),IFERROR(VLOOKUP(Workflow!C8,Agent_Definitions!A:E,5,FALSE),"")))) | H8: =IF(Workflow!B8="","",IF(Workflow!I8<>"",Workflow!I8,IFERROR(VLOOKUP(Workflow!C8,Builtin_Agents!A:F,6,FALSE),IFERROR(VLOOKUP(Workflow!C8,Agent_Definitions!A:F,6,FALSE),"")))) | I8: =IF(Workflow!B8="","",Workflow!J8) | J8: =IF(Workflow!B8="","",Workflow!K8) | K8: =IF(Workflow!B8="","",Workflow!L8)
A9: =IF(Workflow!A9="","",Workflow!A9) | B9: =IF(Workflow!B9="","",Workflow!B9) | C9: =IF(Workflow!B9="","",IF(Workflow!D9<>"",Workflow!D9,IFERROR(VLOOKUP(Workflow!C9,Builtin_Agents!A:B,2,FALSE),IFERROR(VLOOKUP(Workflow!C9,Agent_Definitions!A:B,2,FALSE),"")))) | D9: =IF(Workflow!B9="","",IF(LEFT(Workflow!E9,1)="@",IFERROR(VLOOKUP(MID(Workflow!E9,2,100),Prompts!A:C,3,FALSE),Workflow!E9),Workflow!E9)) | E9: =IF(Workflow!B9="","",Workflow!F9) | F9: =IF(Workflow!B9="","",IF(Workflow!G9<>"",Workflow!G9,IFERROR(VLOOKUP(Workflow!C9,Builtin_Agents!A:H,8,FALSE),IFERROR(VLOOKUP(Workflow!C9,Agent_Definitions!A:H,8,FALSE),"")))) | G9: =IF(Workflow!B9="","",IF(Workflow!H9<>"",Workflow!H9,IFERROR(VLOOKUP(Workflow!C9,Builtin_Agents!A:E,5,FALSE),IFERROR(VLOOKUP(Workflow!C9,Agent_Definitions!A:E,5,FALSE),"")))) | H9: =IF(Workflow!B9="","",IF(Workflow!I9<>"",Workflow!I9,IFERROR(VLOOKUP(Workflow!C9,Builtin_Agents!A:F,6,FALSE),IFERROR(VLOOKUP(Workflow!C9,Agent_Definitions!A:F,6,FALSE),"")))) | I9: =IF(Workflow!B9="","",Workflow!J9) | J9: =IF(Workflow!B9="","",Workflow!K9) | K9: =IF(Workflow!B9="","",Workflow!L9)
A10: =IF(Workflow!A10="","",Workflow!A10) | B10: =IF(Workflow!B10="","",Workflow!B10) | C10: =IF(Workflow!B10="","",IF(Workflow!D10<>"",Workflow!D10,IFERROR(VLOOKUP(Workflow!C10,Builtin_Agents!A:B,2,FALSE),IFERROR(VLOOKUP(Workflow!C10,Agent_Definitions!A:B,2,FALSE),"")))) | D10: =IF(Workflow!B10="","",IF(LEFT(Workflow!E10,1)="@",IFERROR(VLOOKUP(MID(Workflow!E10,2,100),Prompts!A:C,3,FALSE),Workflow!E10),Workflow!E10)) | E10: =IF(Workflow!B10="","",Workflow!F10) | F10: =IF(Workflow!B10="","",IF(Workflow!G10<>"",Workflow!G10,IFERROR(VLOOKUP(Workflow!C10,Builtin_Agents!A:H,8,FALSE),IFERROR(VLOOKUP(Workflow!C10,Agent_Definitions!A:H,8,FALSE),"")))) | G10: =IF(Workflow!B10="","",IF(Workflow!H10<>"",Workflow!H10,IFERROR(VLOOKUP(Workflow!C10,Builtin_Agents!A:E,5,FALSE),IFERROR(VLOOKUP(Workflow!C10,Agent_Definitions!A:E,5,FALSE),"")))) | H10: =IF(Workflow!B10="","",IF(Workflow!I10<>"",Workflow!I10,IFERROR(VLOOKUP(Workflow!C10,Builtin_Agents!A:F,6,FALSE),IFERROR(VLOOKUP(Workflow!C10,Agent_Definitions!A:F,6,FALSE),"")))) | I10: =IF(Workflow!B10="","",Workflow!J10) | J10: =IF(Workflow!B10="","",Workflow!K10) | K10: =IF(Workflow!B10="","",Workflow!L10)
A11: =IF(Workflow!A11="","",Workflow!A11) | B11: =IF(Workflow!B11="","",Workflow!B11) | C11: =IF(Workflow!B11="","",IF(Workflow!D11<>"",Workflow!D11,IFERROR(VLOOKUP(Workflow!C11,Builtin_Agents!A:B,2,FALSE),IFERROR(VLOOKUP(Workflow!C11,Agent_Definitions!A:B,2,FALSE),"")))) | D11: =IF(Workflow!B11="","",IF(LEFT(Workflow!E11,1)="@",IFERROR(VLOOKUP(MID(Workflow!E11,2,100),Prompts!A:C,3,FALSE),Workflow!E11),Workflow!E11)) | E11: =IF(Workflow!B11="","",Workflow!F11) | F11: =IF(Workflow!B11="","",IF(Workflow!G11<>"",Workflow!G11,IFERROR(VLOOKUP(Workflow!C11,Builtin_Agents!A:H,8,FALSE),IFERROR(VLOOKUP(Workflow!C11,Agent_Definitions!A:H,8,FALSE),"")))) | G11: =IF(Workflow!B11="","",IF(Workflow!H11<>"",Workflow!H11,IFERROR(VLOOKUP(Workflow!C11,Builtin_Agents!A:E,5,FALSE),IFERROR(VLOOKUP(Workflow!C11,Agent_Definitions!A:E,5,FALSE),"")))) | H11: =IF(Workflow!B11="","",IF(Workflow!I11<>"",Workflow!I11,IFERROR(VLOOKUP(Workflow!C11,Builtin_Agents!A:F,6,FALSE),IFERROR(VLOOKUP(Workflow!C11,Agent_Definitions!A:F,6,FALSE),"")))) | I11: =IF(Workflow!B11="","",Workflow!J11) | J11: =IF(Workflow!B11="","",Workflow!K11) | K11: =IF(Workflow!B11="","",Workflow!L11)
A12: =IF(Workflow!A12="","",Workflow!A12) | B12: =IF(Workflow!B12="","",Workflow!B12) | C12: =IF(Workflow!B12="","",IF(Workflow!D12<>"",Workflow!D12,IFERROR(VLOOKUP(Workflow!C12,Builtin_Agents!A:B,2,FALSE),IFERROR(VLOOKUP(Workflow!C12,Agent_Definitions!A:B,2,FALSE),"")))) | D12: =IF(Workflow!B12="","",IF(LEFT(Workflow!E12,1)="@",IFERROR(VLOOKUP(MID(Workflow!E12,2,100),Prompts!A:C,3,FALSE),Workflow!E12),Workflow!E12)) | E12: =IF(Workflow!B12="","",Workflow!F12) | F12: =IF(Workflow!B12="","",IF(Workflow!G12<>"",Workflow!G12,IFERROR(VLOOKUP(Workflow!C12,Builtin_Agents!A:H,8,FALSE),IFERROR(VLOOKUP(Workflow!C12,Agent_Definitions!A:H,8,FALSE),"")))) | G12: =IF(Workflow!B12="","",IF(Workflow!H12<>"",Workflow!H12,IFERROR(VLOOKUP(Workflow!C12,Builtin_Agents!A:E,5,FALSE),IFERROR(VLOOKUP(Workflow!C12,Agent_Definitions!A:E,5,FALSE),"")))) | H12: =IF(Workflow!B12="","",IF(Workflow!I12<>"",Workflow!I12,IFERROR(VLOOKUP(Workflow!C12,Builtin_Agents!A:F,6,FALSE),IFERROR(VLOOKUP(Workflow!C12,Agent_Definitions!A:F,6,FALSE),"")))) | I12: =IF(Workflow!B12="","",Workflow!J12) | J12: =IF(Workflow!B12="","",Workflow!K12) | K12: =IF(Workflow!B12="","",Workflow!L12)
A13: =IF(Workflow!A13="","",Workflow!A13) | B13: =IF(Workflow!B13="","",Workflow!B13) | C13: =IF(Workflow!B13="","",IF(Workflow!D13<>"",Workflow!D13,IFERROR(VLOOKUP(Workflow!C13,Builtin_Agents!A:B,2,FALSE),IFERROR(VLOOKUP(Workflow!C13,Agent_Definitions!A:B,2,FALSE),"")))) | D13: =IF(Workflow!B13="","",IF(LEFT(Workflow!E13,1)="@",IFERROR(VLOOKUP(MID(Workflow!E13,2,100),Prompts!A:C,3,FALSE),Workflow!E13),Workflow!E13)) | E13: =IF(Workflow!B13="","",Workflow!F13) | F13: =IF(Workflow!B13="","",IF(Workflow!G13<>"",Workflow!G13,IFERROR(VLOOKUP(Workflow!C13,Builtin_Agents!A:H,8,FALSE),IFERROR(VLOOKUP(Workflow!C13,Agent_Definitions!A:H,8,FALSE),"")))) | G13: =IF(Workflow!B13="","",IF(Workflow!H13<>"",Workflow!H13,IFERROR(VLOOKUP(Workflow!C13,Builtin_Agents!A:E,5,FALSE),IFERROR(VLOOKUP(Workflow!C13,Agent_Definitions!A:E,5,FALSE),"")))) | H13: =IF(Workflow!B13="","",IF(Workflow!I13<>"",Workflow!I13,IFERROR(VLOOKUP(Workflow!C13,Builtin_Agents!A:F,6,FALSE),IFERROR(VLOOKUP(Workflow!C13,Agent_Definitions!A:F,6,FALSE),"")))) | I13: =IF(Workflow!B13="","",Workflow!J13) | J13: =IF(Workflow!B13="","",Workflow!K13) | K13: =IF(Workflow!B13="","",Workflow!L13)
A14: =IF(Workflow!A14="","",Workflow!A14) | B14: =IF(Workflow!B14="","",Workflow!B14) | C14: =IF(Workflow!B14="","",IF(Workflow!D14<>"",Workflow!D14,IFERROR(VLOOKUP(Workflow!C14,Builtin_Agents!A:B,2,FALSE),IFERROR(VLOOKUP(Workflow!C14,Agent_Definitions!A:B,2,FALSE),"")))) | D14: =IF(Workflow!B14="","",IF(LEFT(Workflow!E14,1)="@",IFERROR(VLOOKUP(MID(Workflow!E14,2,100),Prompts!A:C,3,FALSE),Workflow!E14),Workflow!E14)) | E14: =IF(Workflow!B14="","",Workflow!F14) | F14: =IF(Workflow!B14="","",IF(Workflow!G14<>"",Workflow!G14,IFERROR(VLOOKUP(Workflow!C14,Builtin_Agents!A:H,8,FALSE),IFERROR(VLOOKUP(Workflow!C14,Agent_Definitions!A:H,8,FALSE),"")))) | G14: =IF(Workflow!B14="","",IF(Workflow!H14<>"",Workflow!H14,IFERROR(VLOOKUP(Workflow!C14,Builtin_Agents!A:E,5,FALSE),IFERROR(VLOOKUP(Workflow!C14,Agent_Definitions!A:E,5,FALSE),"")))) | H14: =IF(Workflow!B14="","",IF(Workflow!I14<>"",Workflow!I14,IFERROR(VLOOKUP(Workflow!C14,Builtin_Agents!A:F,6,FALSE),IFERROR(VLOOKUP(Workflow!C14,Agent_Definitions!A:F,6,FALSE),"")))) | I14: =IF(Workflow!B14="","",Workflow!J14) | J14: =IF(Workflow!B14="","",Workflow!K14) | K14: =IF(Workflow!B14="","",Workflow!L14)
A15: =IF(Workflow!A15="","",Workflow!A15) | B15: =IF(Workflow!B15="","",Workflow!B15) | C15: =IF(Workflow!B15="","",IF(Workflow!D15<>"",Workflow!D15,IFERROR(VLOOKUP(Workflow!C15,Builtin_Agents!A:B,2,FALSE),IFERROR(VLOOKUP(Workflow!C15,Agent_Definitions!A:B,2,FALSE),"")))) | D15: =IF(Workflow!B15="","",IF(LEFT(Workflow!E15,1)="@",IFERROR(VLOOKUP(MID(Workflow!E15,2,100),Prompts!A:C,3,FALSE),Workflow!E15),Workflow!E15)) | E15: =IF(Workflow!B15="","",Workflow!F15) | F15: =IF(Workflow!B15="","",IF(Workflow!G15<>"",Workflow!G15,IFERROR(VLOOKUP(Workflow!C15,Builtin_Agents!A:H,8,FALSE),IFERROR(VLOOKUP(Workflow!C15,Agent_Definitions!A:H,8,FALSE),"")))) | G15: =IF(Workflow!B15="","",IF(Workflow!H15<>"",Workflow!H15,IFERROR(VLOOKUP(Workflow!C15,Builtin_Agents!A:E,5,FALSE),IFERROR(VLOOKUP(Workflow!C15,Agent_Definitions!A:E,5,FALSE),"")))) | H15: =IF(Workflow!B15="","",IF(Workflow!I15<>"",Workflow!I15,IFERROR(VLOOKUP(Workflow!C15,Builtin_Agents!A:F,6,FALSE),IFERROR(VLOOKUP(Workflow!C15,Agent_Definitions!A:F,6,FALSE),"")))) | I15: =IF(Workflow!B15="","",Workflow!J15) | J15: =IF(Workflow!B15="","",Workflow!K15) | K15: =IF(Workflow!B15="","",Workflow!L15)
... A199: =IF(Workflow!A199="","",Workflow!A199) | B199: =IF(Workflow!B199="","",Workflow!B199) | C199: =IF(Workflow!B199="","",IF(Workflow!D199<>"",Workflow!D199,IFERROR(VLOOKUP(Workflow!C199,Builtin_Agents!A:B,2,FALSE),IFERROR(VLOOKUP(Workflow!C199,Agent_Definitions!A:B,2,FALSE),"")))) | D199: =IF(Workflow!B199="","",IF(LEFT(Workflow!E199,1)="@",IFERROR(VLOOKUP(MID(Workflow!E199,2,100),Prompts!A:C,3,FALSE),Workflow!E199),Workflow!E199)) | E199: =IF(Workflow!B199="","",Workflow!F199) | F199: =IF(Workflow!B199="","",IF(Workflow!G199<>"",Workflow!G199,IFERROR(VLOOKUP(Workflow!C199,Builtin_Agents!A:H,8,FALSE),IFERROR(VLOOKUP(Workflow!C199,Agent_Definitions!A:H,8,FALSE),"")))) | G199: =IF(Workflow!B199="","",IF(Workflow!H199<>"",Workflow!H199,IFERROR(VLOOKUP(Workflow!C199,Builtin_Agents!A:E,5,FALSE),IFERROR(VLOOKUP(Workflow!C199,Agent_Definitions!A:E,5,FALSE),"")))) | H199: =IF(Workflow!B199="","",IF(Workflow!I199<>"",Workflow!I199,IFERROR(VLOOKUP(Workflow!C199,Builtin_Agents!A:F,6,FALSE),IFERROR(VLOOKUP(Workflow!C199,Agent_Definitions!A:F,6,FALSE),"")))) | I199: =IF(Workflow!B199="","",Workflow!J199) | J199: =IF(Workflow!B199="","",Workflow!K199) | K199: =IF(Workflow!B199="","",Workflow!L199)

Sheet Help
A1: AgentMap Workflow Builder - Help & Instructions
B3: OVERVIEW
B4: This Excel workbook helps you design AgentMap workflows visually.
B5: Define agents, create prompts, build workflows, and export to CSV.
B7: SHEETS
B8: 1. Agent_Definitions | C8: Define your custom agents with their configurations
B9: 2. Prompts | C9: Create reusable prompts that can be referenced anywhere
B10: 3. Workflow | C10: Build your workflow by selecting agents and defining flow
B11: 4. Builtin_Agents | C11: Reference sheet of all available builtin agents
B12: 5. CSV_Export | C12: Final output - copy this to export as CSV
B14: HOW TO USE
B15: Step 1: | C15: Define any custom agents in Agent_Definitions tab
B16: Step 2: | C16: Create reusable prompts in Prompts tab (optional)
B17: Step 3: | C17: Build workflow in Workflow tab:
B18: - Set GraphName | C18: (same for all nodes in a workflow)
B19: - Add Node names | C19: (unique within the workflow)
B20: - Select Agent_ID | C20: (from dropdown or type custom)
B21: - Set prompts | C21: (direct text or @Prompt_ID reference)
B22: - Define routing | C22: (Edge, Success_Next, or Failure_Next)
B23: Step 4: | C23: Review CSV_Export tab
B24: Step 5: | C24: Export: Select all in CSV_Export, copy, paste to .csv file
B26: ROUTING RULES
B27: Simple flow: | C27: Use Edge column (e.g., 'NextNode')
B28: Conditional flow: | C28: Use Success_Next and Failure_Next
B29: Parallel flow: | C29: Use pipe separator (e.g., 'Node1|Node2|Node3')
B30: Important: | C30: Don't mix Edge with Success_Next/Failure_Next
B32: FIELD FORMAT
B33: Input_Fields: | C33: Pipe-separated (e.g., 'query|context|options')
B34: Context: | C34: Valid JSON (e.g., {"temperature": 0.7})
B35: Prompt refs: | C35: Use @Prompt_ID to reference Prompts sheet
B37: AGENT TYPES
B38: Core: | C38: echo, default, input, branching, human, graph
B39: LLM: | C39: claude, gpt, gemini, llm (generic)
B40: Storage: | C40: csv_reader/writer, json_reader/writer, file_reader/writer
B41: Mixed: | C41: summary, orchestrator, tool_agent
B43: TIPS
B44: - Use builtin agents | C44: for common tasks (already configured)
B45: - Auto-fill works | C45: Input/Output/Context auto-populate from agent
B46: - Override as needed | C46: Fill in fields to override agent defaults
B47: - Notes column | C47: Use it! Not exported, just for your reference
...

Sheet _Helper
A1: builtin_echo
A2: builtin_default
A3: builtin_input
A4: builtin_branching
A5: builtin_success
A6: builtin_failure
A7: builtin_suspend
A8: builtin_human_approval
A9: builtin_human_choice
A10: builtin_human_text
A11: builtin_human_edit
A12: builtin_graph
... A27: builtin_tool_agent
A28: =IF(Agent_Definitions!A4="","",Agent_Definitions!A4)
A29: =IF(Agent_Definitions!A5="","",Agent_Definitions!A5)
A30: =IF(Agent_Definitions!A6="","",Agent_Definitions!A6)
A31: =IF(Agent_Definitions!A7="","",Agent_Definitions!A7)
A32: =IF(Agent_Definitions!A8="","",Agent_Definitions!A8)
A33: =IF(Agent_Definitions!A9="","",Agent_Definitions!A9)
A34: =IF(Agent_Definitions!A10="","",Agent_Definitions!A10)
A35: =IF(Agent_Definitions!A11="","",Agent_Definitions!A11)
A36: =IF(Agent_Definitions!A12="","",Agent_Definitions!A12)
A37: =IF(Agent_Definitions!A13="","",Agent_Definitions!A13)
A38: =IF(Agent_Definitions!A14="","",Agent_Definitions!A14)
A39: =IF(Agent_Definitions!A15="","",Agent_Definitions!A15)
... A77: =IF(Agent_Definitions!A53="","",Agent_Definitions!A53)
